<sdf version='1.10'>
  <model name='haro380'>
    <link name='base_link'>
      <inertial>
        <pose>-0.0015527 1.1895000000000001e-09 0.018512000000000001 0 0 0</pose>
        <mass>0.70953999999999995</mass>
        <inertia>
          <ixx>0.00044737999999999999</ixx>
          <ixy>2.7050999999999999e-11</ixy>
          <ixz>-7.1743000000000001e-06</ixz>
          <iyy>0.00048680000000000001</iyy>
          <iyz>8.4894000000000006e-12</iyz>
          <izz>0.00072225999999999996</izz>
        </inertia>
      </inertial>
      <collision name='base_link_collision'>
        <pose>0 0 0 0 0 0</pose>
        <geometry>
          <mesh>
            <scale>1 1 1</scale>
            <uri>model://wlkata_haro380_description/meshes/base_link.STL</uri>
          </mesh>
        </geometry>
      </collision>
      <visual name='base_link_visual'>
        <pose>0 0 0 0 0 0</pose>
        <geometry>
          <mesh>
            <scale>1 1 1</scale>
            <uri>model://wlkata_haro380_description/meshes/base_link.STL</uri>
          </mesh>
        </geometry>
        <material>
          <diffuse>0.833337545 0.872550011 0.960787535 1</diffuse>
          <ambient>0.833337545 0.872550011 0.960787535 1</ambient>
        </material>
      </visual>
    </link>
    <joint name='joint1' type='revolute'>
      <pose relative_to='base_link'>0 0 0.11 0 0 0</pose>
      <parent>base_link</parent>
      <child>link1</child>
      <axis>
        <xyz>0 0 1</xyz>
        <limit>
          <lower>-2.4434</lower>
          <upper>3.3161</upper>
          <effort>100</effort>
          <velocity>1</velocity>
        </limit>
        <dynamics>
          <spring_reference>0</spring_reference>
          <spring_stiffness>0</spring_stiffness>
        </dynamics>
      </axis>
    </joint>
    <link name='link1'>
      <pose relative_to='joint1'>0 0 0 0 0 0</pose>
      <inertial>
        <pose>0.012411999999999999 0.0049252999999999996 -0.019702999999999998 0 0 0</pose>
        <mass>3.2867999999999999</mass>
        <inertia>
          <ixx>0.0015911</ixx>
          <ixy>-4.7905999999999998e-05</ixy>
          <ixz>-9.0391999999999998e-05</ixz>
          <iyy>0.0021940000000000002</iyy>
          <iyz>-1.2833999999999999e-05</iyz>
          <izz>0.0023758999999999998</izz>
        </inertia>
      </inertial>
      <collision name='link1_collision'>
        <pose>0 0 0 0 0 0</pose>
        <geometry>
          <mesh>
            <scale>1 1 1</scale>
            <uri>model://wlkata_haro380_description/meshes/link1.STL</uri>
          </mesh>
        </geometry>
      </collision>
      <visual name='link1_visual'>
        <pose>0 0 0 0 0 0</pose>
        <geometry>
          <mesh>
            <scale>1 1 1</scale>
            <uri>model://wlkata_haro380_description/meshes/link1.STL</uri>
          </mesh>
        </geometry>
        <material>
          <diffuse>1 1 1 1</diffuse>
          <ambient>1 1 1 1</ambient>
        </material>
      </visual>
    </link>
    <joint name='joint2' type='revolute'>
      <pose relative_to='link1'>0.051999999999999998 0 0 1.5707926536057681 -1.5707926536662187 3.1415926535746808</pose>
      <parent>link1</parent>
      <child>link2</child>
      <axis>
        <xyz>0 0 1</xyz>
        <limit>
          <lower>-1.1344000000000001</lower>
          <upper>1.3962000000000001</upper>
          <effort>100</effort>
          <velocity>1</velocity>
        </limit>
        <dynamics>
          <spring_reference>0</spring_reference>
          <spring_stiffness>0</spring_stiffness>
        </dynamics>
      </axis>
    </joint>
    <link name='link2'>
      <pose relative_to='joint2'>0 0 0 0 0 0</pose>
      <inertial>
        <pose>0.067573999999999995 -0.00018270999999999999 -0.050271999999999997 0 0 0</pose>
        <mass>1.1845000000000001</mass>
        <inertia>
          <ixx>0.00023546</ixx>
          <ixy>-1.5716999999999999e-05</ixy>
          <ixz>-3.4595999999999999e-05</ixz>
          <iyy>0.0035522000000000001</iyy>
          <iyz>-1.0674999999999999e-06</iyz>
          <izz>0.0037052000000000001</izz>
        </inertia>
      </inertial>
      <collision name='link2_collision'>
        <pose>0 0 0 0 0 0</pose>
        <geometry>
          <mesh>
            <scale>1 1 1</scale>
            <uri>model://wlkata_haro380_description/meshes/link2.STL</uri>
          </mesh>
        </geometry>
      </collision>
      <visual name='link2_visual'>
        <pose>0 0 0 0 0 0</pose>
        <geometry>
          <mesh>
            <scale>1 1 1</scale>
            <uri>model://wlkata_haro380_description/meshes/link2.STL</uri>
          </mesh>
        </geometry>
        <material>
          <diffuse>0.833337545 0.872550011 0.960787535 1</diffuse>
          <ambient>0.833337545 0.872550011 0.960787535 1</ambient>
        </material>
      </visual>
    </link>
    <joint name='joint3' type='revolute'>
      <pose relative_to='link2'>0.13600000000000001 0 0 0 0 0</pose>
      <parent>link2</parent>
      <child>link3</child>
      <axis>
        <xyz>0 0 1</xyz>
        <limit>
          <lower>-3.2288000000000001</lower>
          <upper>1.2217</upper>
          <effort>100</effort>
          <velocity>1</velocity>
        </limit>
        <dynamics>
          <spring_reference>0</spring_reference>
          <spring_stiffness>0</spring_stiffness>
        </dynamics>
      </axis>
    </joint>
    <link name='link3'>
      <pose relative_to='joint3'>0 0 0 0 0 0</pose>
      <inertial>
        <pose>0.00078233999999999997 0.018435 0.012037000000000001 0 0 0</pose>
        <mass>0.55264999999999997</mass>
        <inertia>
          <ixx>0.00044119999999999999</ixx>
          <ixy>-2.4265e-06</ixy>
          <ixz>1.8871000000000001e-08</ixz>
          <iyy>0.00017320000000000001</iyy>
          <iyz>-5.3017000000000004e-07</iyz>
          <izz>0.00039554999999999999</izz>
        </inertia>
      </inertial>
      <collision name='link3_collision'>
        <pose>0 0 0 0 0 0</pose>
        <geometry>
          <mesh>
            <scale>1 1 1</scale>
            <uri>model://wlkata_haro380_description/meshes/link3.STL</uri>
          </mesh>
        </geometry>
      </collision>
      <visual name='link3_visual'>
        <pose>0 0 0 0 0 0</pose>
        <geometry>
          <mesh>
            <scale>1 1 1</scale>
            <uri>model://wlkata_haro380_description/meshes/link3.STL</uri>
          </mesh>
        </geometry>
        <material>
          <diffuse>0.833337545 0.872550011 0.960787535 1</diffuse>
          <ambient>0.833337545 0.872550011 0.960787535 1</ambient>
        </material>
      </visual>
    </link>
    <joint name='joint4' type='revolute'>
      <pose relative_to='link3'>0 0.20999999999999999 0 -1.5708 0 0</pose>
      <parent>link3</parent>
      <child>link4</child>
      <axis>
        <xyz>0 0 1</xyz>
        <limit>
          <lower>-2.7052</lower>
          <upper>2.7052</upper>
          <effort>100</effort>
          <velocity>1</velocity>
        </limit>
        <dynamics>
          <spring_reference>0</spring_reference>
          <spring_stiffness>0</spring_stiffness>
        </dynamics>
      </axis>
    </joint>
    <link name='link4'>
      <pose relative_to='joint4'>0 0 0 0 0 0</pose>
      <inertial>
        <pose>7.3741000000000003e-06 -0.0063825000000000002 -0.050305999999999997 0 0 0</pose>
        <mass>0.25489000000000001</mass>
        <inertia>
          <ixx>0.00010467999999999999</ixx>
          <ixy>2.6883e-08</ixy>
          <ixz>-7.2123000000000003e-08</ixz>
          <iyy>8.7118000000000002e-05</iyy>
          <iyz>-8.4914999999999995e-07</iyz>
          <izz>6.9535000000000004e-05</izz>
        </inertia>
      </inertial>
      <collision name='link4_collision'>
        <pose>0 0 0 0 0 0</pose>
        <geometry>
          <mesh>
            <scale>1 1 1</scale>
            <uri>model://wlkata_haro380_description/meshes/link4.STL</uri>
          </mesh>
        </geometry>
      </collision>
      <visual name='link4_visual'>
        <pose>0 0 0 0 0 0</pose>
        <geometry>
          <mesh>
            <scale>1 1 1</scale>
            <uri>model://wlkata_haro380_description/meshes/link4.STL</uri>
          </mesh>
        </geometry>
        <material>
          <diffuse>0.990199983 1 1 1</diffuse>
          <ambient>0.990199983 1 1 1</ambient>
        </material>
      </visual>
    </link>
    <joint name='joint5' type='revolute'>
      <pose relative_to='link4'>0 0 0 -1.5707926536057684 -1.5707926536057681 -3.1415926535746808</pose>
      <parent>link4</parent>
      <child>link5</child>
      <axis>
        <xyz>0 0 1</xyz>
        <limit>
          <lower>-3.5779000000000001</lower>
          <upper>0.34899999999999998</upper>
          <effort>100</effort>
          <velocity>1</velocity>
        </limit>
        <dynamics>
          <spring_reference>0</spring_reference>
          <spring_stiffness>0</spring_stiffness>
        </dynamics>
      </axis>
    </joint>
    <link name='link5'>
      <pose relative_to='joint5'>0 0 0 0 0 0</pose>
      <inertial>
        <pose>-0.0021959000000000002 0.0062243999999999997 -0.0019613 0 0 0</pose>
        <mass>0.15956999999999999</mass>
        <inertia>
          <ixx>4.2827999999999997e-05</ixx>
          <ixy>-3.8956000000000002e-08</ixy>
          <ixz>3.9003000000000001e-07</ixz>
          <iyy>3.7647000000000001e-05</iyy>
          <iyz>-1.1086000000000001e-06</iyz>
          <izz>5.6273000000000001e-05</izz>
        </inertia>
      </inertial>
      <collision name='link5_collision'>
        <pose>0 0 0 0 0 0</pose>
        <geometry>
          <mesh>
            <scale>1 1 1</scale>
            <uri>model://wlkata_haro380_description/meshes/link5.STL</uri>
          </mesh>
        </geometry>
      </collision>
      <visual name='link5_visual'>
        <pose>0 0 0 0 0 0</pose>
        <geometry>
          <mesh>
            <scale>1 1 1</scale>
            <uri>model://wlkata_haro380_description/meshes/link5.STL</uri>
          </mesh>
        </geometry>
        <material>
          <diffuse>0.833337545 0.872550011 0.960787535 1</diffuse>
          <ambient>0.833337545 0.872550011 0.960787535 1</ambient>
        </material>
      </visual>
    </link>
    <joint name='joint6' type='revolute'>
      <pose relative_to='link5'>0 0 0 1.5708 0 0</pose>
      <parent>link5</parent>
      <child>link6</child>
      <axis>
        <xyz>0 0 1</xyz>
        <limit>
          <lower>-3.1415000000000002</lower>
          <upper>3.1415000000000002</upper>
          <effort>100</effort>
          <velocity>1</velocity>
        </limit>
        <dynamics>
          <spring_reference>0</spring_reference>
          <spring_stiffness>0</spring_stiffness>
        </dynamics>
      </axis>
    </joint>
    <link name='link6'>
      <pose relative_to='joint6'>0 0 0 0 0 0</pose>
      <inertial>
        <pose>3.9564000000000003e-05 -3.6452999999999998e-05 -0.046127000000000001 0 0 0</pose>
        <mass>0.0055786000000000004</mass>
        <inertia>
          <ixx>5.0073000000000001e-07</ixx>
          <ixy>-1.9287000000000002e-09</ixy>
          <ixz>2.6797999999999999e-10</ixz>
          <iyy>4.8918999999999995e-07</iyy>
          <iyz>-3.8083000000000002e-10</iyz>
          <izz>8.9393000000000001e-07</izz>
        </inertia>
      </inertial>
      <collision name='link6_collision'>
        <pose>0 0 0 0 0 0</pose>
        <geometry>
          <mesh>
            <scale>1 1 1</scale>
            <uri>model://wlkata_haro380_description/meshes/link6.STL</uri>
          </mesh>
        </geometry>
      </collision>
      <visual name='link6_visual'>
        <pose>0 0 0 0 0 0</pose>
        <geometry>
          <mesh>
            <scale>1 1 1</scale>
            <uri>model://wlkata_haro380_description/meshes/link6.STL</uri>
          </mesh>
        </geometry>
        <material>
          <diffuse>0.833337545 0.872550011 0.960787535 1</diffuse>
          <ambient>0.833337545 0.872550011 0.960787535 1</ambient>
        </material>
      </visual>
    </link>
    <plugin name='gazebo_ros_control' filename='libgazebo_ros_control.so'>
      <robotNamespace>/</robotNamespace>
      <robotSimType>gz_sim/RobotSimType</robotSimType>
    </plugin>
    <plugin name='gazebo_ros_control' filename='libgazebo_ros_control.so'>
      <robotNamespace>/</robotNamespace>
      <robotSimType>gz_sim/RobotSimType</robotSimType>
    </plugin>
    <plugin name='gazebo_ros_control' filename='libgazebo_ros_control.so'>
      <robotNamespace>/</robotNamespace>
      <robotSimType>gz_sim/RobotSimType</robotSimType>
    </plugin>
    <plugin name='gazebo_ros_control' filename='libgazebo_ros_control.so'>
      <robotNamespace>/</robotNamespace>
      <robotSimType>gz_sim/RobotSimType</robotSimType>
    </plugin>
  </model>
</sdf>
